---------------------------------------------
Dataset       : aia211
Configuration : aia211
Model         : mau
---------------------------------------------
Initializing models
save results : 202210232244
Loading train dataset finished, with size: 1000
Loading val dataset finished, with size: 24
Loading test dataset finished, with size: 12
------------- epoch: 1 / 100 ----------------
Train with 250 batch
/home/sasaki/.local/lib/python3.6/site-packages/torch/cuda/__init__.py:143: UserWarning: 
NVIDIA RTX A6000 with CUDA capability sm_86 is not compatible with the current PyTorch installation.
The current PyTorch install supports CUDA capabilities sm_37 sm_50 sm_60 sm_70.
If you want to use the NVIDIA RTX A6000 GPU with PyTorch, please check the instructions at https://pytorch.org/get-started/locally/

  warnings.warn(incompatible_device_warn.format(device_name, capability, " ".join(arch_list), device_name))
Traceback (most recent call last):
  File "run.py", line 252, in <module>
    train_wrapper(model)
  File "run.py", line 208, in train_wrapper
    loss = list(trainer.train(model, ims, real_input_flag, args, itr))
  File "/home/sasaki/MAU/core/trainer.py", line 13, in train
    _, loss_l1, loss_l2 = model.train(ims, real_input_flag, itr)
  File "/home/sasaki/MAU/core/models/model_factory.py", line 55, in train
    next_frames = self.network(frames_tensor, mask_tensor)
  File "/home/sasaki/.local/lib/python3.6/site-packages/torch/nn/modules/module.py", line 1102, in _call_impl
    return forward_call(*input, **kwargs)
  File "/home/sasaki/MAU/core/models/MAU.py", line 104, in forward
    mask_true = mask_true.permute(0, 1, 4, 2, 3).contiguous()
RuntimeError: CUDA error: no kernel image is available for execution on the device
CUDA kernel errors might be asynchronously reported at some other API call,so the stacktrace below might be incorrect.
For debugging consider passing CUDA_LAUNCH_BLOCKING=1.
Traceback (most recent call last):
  File "/usr/local/lib/python3.9/site-packages/pynvml.py", line 644, in _LoadNvmlLibrary
    nvmlLib = CDLL("libnvidia-ml.so.1")
  File "/usr/local/lib/python3.9/ctypes/__init__.py", line 374, in __init__
    self._handle = _dlopen(self._name, mode)
OSError: libnvidia-ml.so.1: cannot open shared object file: No such file or directory

During handling of the above exception, another exception occurred:

Traceback (most recent call last):
  File "/home/MAU/run.py", line 18, in <module>
    pynvml.nvmlInit()
  File "/usr/local/lib/python3.9/site-packages/pynvml.py", line 608, in nvmlInit
    _LoadNvmlLibrary()
  File "/usr/local/lib/python3.9/site-packages/pynvml.py", line 646, in _LoadNvmlLibrary
    _nvmlCheckReturn(NVML_ERROR_LIBRARY_NOT_FOUND)
  File "/usr/local/lib/python3.9/site-packages/pynvml.py", line 310, in _nvmlCheckReturn
    raise NVMLError(ret)
pynvml.NVMLError_LibraryNotFound: NVML Shared Library Not Found
